<?xml version="1.0" ?>
<robot name="ur3" xmlns:xacro="http://www.ros.org/wiki/xacro">

<!-- origin values for each link -->
 <xacro:property name="chassis_origin">
    <origin xyz="0 0 -0.1" rpy="0 0 0"/>
 </xacro:property>
 <xacro:property name="caster_origin">
    <origin xyz="-0.15 0 -0.15" rpy="0 0 0"/>
 </xacro:property> 
<xacro:property name="left_wheel_origin">
    <origin xyz="0.3 0.12 -0.05" rpy="0 1.5707 1.5707"/>
 </xacro:property>
<xacro:property name="right_wheel_origin">
    <origin xyz="0.3 -0.12 -0.05" rpy="0 1.5707 1.5707"/>
 </xacro:property> 

<!-- chassis link -->

   <link name="chassis">
    <visual name='chassis_visual'>
      <geometry>
        <box size="0.7 0.2 0.1"/>
      </geometry>
      <xacro:insert_block name="chassis_origin"/>
    </visual>
    <collision name='chassis_collision'>
      <geometry>
        <box size="0.7 0.2 0.1"/>
      </geometry>
      <xacro:insert_block name="chassis_origin"/>
    </collision>
    <inertial name='chassis_inertial'>
      <mass value="2.0"/>
      <xacro:insert_block name="chassis_origin"/>
      <inertia ixx="0.0030531654454" ixy="0.0" ixz="0.0" iyy="0.0030531654454" iyz="0.0" izz="0.005625"/>
    </inertial>
    <visual name='caster_visual'>
      <geometry>
        <sphere radius=".05" />
      </geometry>
      <xacro:insert_block name="caster_origin"/>
    </visual> 
    <collision name='caster_collision'>
      <geometry>
        <sphere radius=".05" />
      </geometry>
      <xacro:insert_block name="caster_origin"/>
      <surface>
        <friction>
          <ode>
            <mu>0</mu>
            <mu2>0</mu2>
            <slip1>1.0</slip1>
            <slip2>1.0</slip2>
          </ode>
        </friction>
      </surface>
    </collision>
    <inertial name='caster_inertial'>
      <mass value="2.0"/>
      <xacro:insert_block name="caster_origin"/>
      <inertia ixx="0.0030531654454" ixy="0.0" ixz="0.0" iyy="0.0030531654454" iyz="0.0" izz="0.005625"/>
    </inertial> 
   </link>

<!-- left wheel joint -->
 
 <joint name="left_wheel_hinge" type="continuous">
    <parent link="chassis"/>
    <child link="left_wheel"/>
    <origin xyz="0.0 0.0 0.05" rpy="0.0 0.0 0.0"/>
    <axis xyz="0 1 0"/> 
    <dynamics damping="0.0" friction="0.0"/>  
  </joint> 

<!-- left wheel link -->

  <link name="left_wheel">
    <collision name="left_collision">
      <geometry>
        <cylinder radius="0.1" length="0.05"/>
      </geometry>
    <xacro:insert_block name="left_wheel_origin"/> 
    </collision>
    <visual name="left_visual">
      <geometry>
        <cylinder radius="0.1" length="0.05"/>
      </geometry>
      <xacro:insert_block name="left_wheel_origin"/>
    </visual>
    <inertial name='left_inertial'>
      <mass value="2.0"/>
      <xacro:insert_block name="left_wheel_origin"/>
      <inertia ixx="0.0030531654454" ixy="0.0" ixz="0.0" iyy="0.0030531654454" iyz="0.0" izz="0.005625"/>
    </inertial>
  </link>   

  <!-- right wheel joint -->
 
 <joint name="right_wheel_hinge" type="continuous">
    <parent link="chassis"/>
    <child link="right_wheel"/>
    <origin xyz="0.0 0.0 0.05" rpy="0.0 0.0 0.0"/>
    <axis xyz="0 1 0"/> 
    <dynamics damping="0.0" friction="0.0"/>  
  </joint> 

<!-- right wheel link -->

  <link name="right_wheel">
    <collision name="right_collision">
      <geometry>
        <cylinder radius="0.1" length="0.05"/>
      </geometry>
    <xacro:insert_block name="right_wheel_origin"/> 
    </collision>
    <visual name="right_visual">
      <geometry>
        <cylinder radius="0.1" length="0.05"/>
      </geometry>
      <xacro:insert_block name="right_wheel_origin"/>
    </visual>
    <inertial name='right_inertial'>
      <mass value="2.0"/>
      <xacro:insert_block name="right_wheel_origin"/>
      <inertia ixx="0.0030531654454" ixy="0.0" ixz="0.0" iyy="0.0030531654454" iyz="0.0" izz="0.005625"/>
    </inertial>
  </link> 
 

</robot>