<?xml version='1.0'?>

<robot xmlns:xacro="http://www.ros.org/wiki/xacro">



  <!-- <xacro:include filename="$(find ur_description)/urdf/myrobot.gazebo" /> -->
  <!-- <xacro:include filename="$(find ur_description)/urdf/materials.xacro" /> -->
  <!-- <xacro:include filename="$(find ur_description)/urdf/macros.xacro" /> -->

  <xacro:macro name="cart_robot">
    <link name='chassis'>
      <pose>0 0 0.1 0 0 0</pose>

      <inertial>
        <mass value="20.0"/>
        <origin xyz="0.0 0 0.1" rpy=" 0 0 0"/>
        <inertia
            ixx="0.5" ixy="0" ixz="0"
            iyy="1.0" iyz="0"
            izz="0.1"
        />
      </inertial>

      <collision name='collision'>
        <geometry>
          <box size=".4 .2 .1"/>
        </geometry>
      </collision>

      <visual name='chassis_visual'>
        <origin xyz="0 0 0" rpy=" 0 0 0"/>
        <geometry>
          <box size=".4 .2 .1"/>
        </geometry>
      </visual>


      <collision name='caster_collision'>
        <origin xyz="-0.15 0 -0.05" rpy=" 0 0 0"/>
        <geometry>
          <sphere radius="0.05"/>
        </geometry>
      </collision>

      <visual name='caster_visual'>
        <origin xyz="-0.15 0 -0.05" rpy=" 0 0 0"/>
        <geometry>
          <sphere radius="0.05"/>
        </geometry>
      </visual>
    </link>


    <link name="left_wheel">
      <!--origin xyz="0.1 0.13 0.1" rpy="0 1.5707 1.5707"/-->
      <collision name="collision">
        <origin xyz="0 0 0" rpy="0 1.5707 1.5707"/>
        <geometry>
          <cylinder radius="0.1" length="0.05"/>
        </geometry>
      </collision>
      <visual name="left_wheel_visual">
        <origin xyz="0 0 0" rpy="0 1.5707 1.5707"/>
        <geometry>
          <cylinder radius="0.1" length="0.05"/>
        </geometry>
      </visual>
      <inertial>
        <origin xyz="0 0 0" rpy="0 1.5707 1.5707"/>
        <mass value="5"/>
        <cylinder_inertia m="5" r="0.1" h="0.05"/>
        <inertia
          ixx="1.0" ixy="0.0" ixz="0.0"
          iyy="1.0" iyz="0.0"
          izz="1.0"/>
      </inertial>
    </link>

    

    <link name="right_wheel">
      <!--origin xyz="0.1 -0.13 0.1" rpy="0 1.5707 1.5707"/-->
      <collision name="collision">
        <origin xyz="0 0 0" rpy="0 1.5707 1.5707"/>
        <geometry>
          <cylinder radius="0.1" length="0.05"/>
        </geometry>
      </collision>
      <visual name="right_wheel_visual">
        <origin xyz="0 0 0" rpy="0 1.5707 1.5707"/>
        <geometry>
          <cylinder radius="0.1" length="0.05"/>
        </geometry>
      </visual>
      <inertial>
        <origin xyz="0 0 0" rpy="0 1.5707 1.5707"/>
        <mass value="5"/>
        <cylinder_inertia m="5" r="0.1" h="0.05"/>
        <inertia
          ixx="1.0" ixy="0.0" ixz="0.0"
          iyy="1.0" iyz="0.0"
          izz="1.0"/>
      </inertial>
    </link>


    <joint type="continuous" name="left_wheel_hinge">
      <origin xyz="0.1 0.15 0" rpy="0 0 0"/>
      <child link="left_wheel"/>
      <parent link="chassis"/>
      <axis xyz="0 1 0" rpy="0 0 0"/>
      <limit effort="10000" velocity="10000"/>
      <joint_properties damping="0.0" friction="0.0"/>
    </joint>

    <joint type="continuous" name="right_wheel_hinge">
      <origin xyz="0.1 -0.15 0" rpy="0 0 0"/>
      <child link="right_wheel"/>
      <parent link="chassis"/>
      <axis xyz="0 1 0" rpy="0 0 0"/>
      <limit effort="10000" velocity="10000"/>
      <joint_properties damping="0.0" friction="0.0"/>
    </joint>

    <transmission name="left_trans">
        <type>transmission_interface/SimpleTransmission</type>
        <joint name="left_wheel_hinge">
          <hardwareInterface>hardware_interface/VelocityJointInterface</hardwareInterface>
        </joint>
        <actuator name="leftMotor">
          <hardwareInterface>VelocityJointInterface</hardwareInterface>
          <mechanicalReduction>1</mechanicalReduction>
        </actuator>
      </transmission>

      <transmission name="right_trans">
        <type>transmission_interface/SimpleTransmission</type>
        <joint name="right_wheel_hinge">
          <hardwareInterface>hardware_interface/VelocityJointInterface</hardwareInterface>
        </joint>
        <actuator name="rightMotor">
          <hardwareInterface>VelocityJointInterface</hardwareInterface>
          <mechanicalReduction>1</mechanicalReduction>
        </actuator>
      </transmission>


    <gazebo>
      <plugin name="differential_drive_controller" filename="libgazebo_ros_diff_drive.so">
        <robotNamespace>/cart_controller</robotNamespace>
        <legacyMode>True</legacyMode>
        <!-- <robotSimType>gazebo_ros_control/DefaultRobotHWSim</robotSimType> -->
        <!-- <bodyName>chassis</bodyName> -->
        <alwaysOn>true</alwaysOn>
        <updateRate>20</updateRate>
        <leftJoint>left_wheel_hinge</leftJoint>
        <rightJoint>right_wheel_hinge</rightJoint>
        <wheelSeparation>0.4</wheelSeparation>
        <wheelDiameter>0.1</wheelDiameter>
        <torque>40</torque>
        <commandTopic>cmd_vel</commandTopic>
        <odometryTopic>odom</odometryTopic>
        <odometryFrame>odom</odometryFrame>
        <robotBaseFrame>base_link</robotBaseFrame>
        <publishWheelTF>true</publishWheelTF>
        <publishOdom>true</publishOdom>
        <publishOdomTF>true</publishOdomTF>
        <publishWheelJointState>true</publishWheelJointState>
        <wheelAcceleration>0.5</wheelAcceleration>
        <wheelTorque>40</wheelTorque>
        <odometrySource>world</odometrySource>
        <publishTf>1</publishTf>
        <rosDebugLevel>na</rosDebugLevel>
      </plugin>
    </gazebo>

    <gazebo reference="chassis">
      <selfCollide>true</selfCollide>
      <mu1>0.0</mu1>
      <mu2>0.0</mu2>
      <material>Gazebo/Orange</material>
    </gazebo>

    <gazebo reference="left_wheel">
      <selfCollide>true</selfCollide>
      <mu1 value="20000.0"/>
      <mu2 value="1000.0"/>
      <material>Gazebo/Black</material>
    </gazebo>

    <gazebo reference="right_wheel">
      <selfCollide>true</selfCollide>
      <mu1 value="20000.0"/>
      <mu2 value="1000.0"/>
      <material>Gazebo/Black</material>
    </gazebo>
  </xacro:macro>

</robot>